[2023-04-08T07:07:02.576+0000] {task_command.py:389} INFO - Running <TaskInstance: io_resto_casa.say_Hi scheduled__2023-04-06T12:50:00+00:00 [up_for_retry]> on host cfece00ff772
[2023-04-08T07:07:09.245+0000] {taskinstance.py:1488} ERROR - Received SIGTERM. Terminating subprocesses.
[2023-04-08T07:07:09.291+0000] {subprocess.py:104} INFO - Sending SIGTERM signal to process group
[2023-04-08T07:07:09.960+0000] {taskinstance.py:1776} ERROR - Task failed with exception
Traceback (most recent call last):
  File "/home/airflow/.local/lib/python3.7/site-packages/airflow/models/taskinstance.py", line 1383, in _run_raw_task
    self._execute_task_with_callbacks(context, test_mode)
  File "/home/airflow/.local/lib/python3.7/site-packages/airflow/models/taskinstance.py", line 1502, in _execute_task_with_callbacks
    task_orig = self.render_templates(context=context)
  File "/home/airflow/.local/lib/python3.7/site-packages/airflow/models/taskinstance.py", line 2123, in render_templates
    original_task.render_template_fields(context)
  File "/home/airflow/.local/lib/python3.7/site-packages/airflow/models/baseoperator.py", line 1178, in render_template_fields
    jinja_env = self.get_template_env()
  File "/home/airflow/.local/lib/python3.7/site-packages/airflow/models/abstractoperator.py", line 163, in get_template_env
    return dag.get_template_env(force_sandboxed=False)
  File "/home/airflow/.local/lib/python3.7/site-packages/airflow/models/dag.py", line 1461, in get_template_env
    "loader": jinja2.FileSystemLoader(searchpath),
  File "/home/airflow/.local/lib/python3.7/site-packages/jinja2/loaders.py", line 179, in __init__
    def __init__(
  File "/home/airflow/.local/lib/python3.7/site-packages/airflow/models/taskinstance.py", line 1490, in signal_handler
    raise AirflowException("Task received SIGTERM signal")
airflow.exceptions.AirflowException: Task received SIGTERM signal
[2023-04-08T07:07:10.891+0000] {taskinstance.py:1332} INFO - Marking task as UP_FOR_RETRY. dag_id=io_resto_casa, task_id=say_Hi, execution_date=20230406T125000, start_date=20230408T070643, end_date=20230408T070710
[2023-04-08T07:07:12.015+0000] {standard_task_runner.py:105} ERROR - Failed to execute job 245 for task say_Hi (Task received SIGTERM signal; 13236)
[2023-04-08T07:09:13.243+0000] {taskinstance.py:1084} INFO - Dependencies not met for <TaskInstance: io_resto_casa.say_Hi scheduled__2023-04-06T12:50:00+00:00 [up_for_retry]>, dependency 'Not In Retry Period' FAILED: Task is not ready for retry yet but will be retried automatically. Current date is 2023-04-08T07:09:13.242437+00:00 and task will be retried at 2023-04-08T07:12:10.654673+00:00.
[2023-04-08T07:09:14.213+0000] {local_task_job.py:151} INFO - Task is not able to be run
[2023-04-08T10:11:53.735+0000] {taskinstance.py:1090} INFO - Dependencies all met for dep_context=non-requeueable deps ti=<TaskInstance: io_resto_casa.say_Hi scheduled__2023-04-06T12:50:00+00:00 [queued]>
[2023-04-08T10:11:54.344+0000] {taskinstance.py:1090} INFO - Dependencies all met for dep_context=requeueable deps ti=<TaskInstance: io_resto_casa.say_Hi scheduled__2023-04-06T12:50:00+00:00 [queued]>
[2023-04-08T10:11:54.434+0000] {taskinstance.py:1288} INFO - 
--------------------------------------------------------------------------------
[2023-04-08T10:11:54.510+0000] {taskinstance.py:1289} INFO - Starting attempt 2 of 3
[2023-04-08T10:11:54.580+0000] {taskinstance.py:1290} INFO - 
--------------------------------------------------------------------------------
[2023-04-08T10:11:58.270+0000] {taskinstance.py:1309} INFO - Executing <Task(BashOperator): say_Hi> on 2023-04-06 12:50:00+00:00
[2023-04-08T10:11:59.395+0000] {standard_task_runner.py:55} INFO - Started process 13502 to run task
[2023-04-08T10:11:59.940+0000] {standard_task_runner.py:82} INFO - Running: ['***', 'tasks', 'run', 'io_resto_casa', 'say_Hi', 'scheduled__2023-04-06T12:50:00+00:00', '--job-id', '273', '--raw', '--subdir', 'DAGS_FOLDER/ciao.py', '--cfg-path', '/tmp/tmppbuxwwq9']
[2023-04-08T10:12:01.610+0000] {standard_task_runner.py:83} INFO - Job 273: Subtask say_Hi
[2023-04-08T10:12:10.399+0000] {task_command.py:389} INFO - Running <TaskInstance: io_resto_casa.say_Hi scheduled__2023-04-06T12:50:00+00:00 [running]> on host cfece00ff772
[2023-04-08T10:12:18.405+0000] {taskinstance.py:1518} INFO - Exporting the following env vars:
AIRFLOW_CTX_DAG_OWNER=***
AIRFLOW_CTX_DAG_ID=io_resto_casa
AIRFLOW_CTX_TASK_ID=say_Hi
AIRFLOW_CTX_EXECUTION_DATE=2023-04-06T12:50:00+00:00
AIRFLOW_CTX_TRY_NUMBER=2
AIRFLOW_CTX_DAG_RUN_ID=scheduled__2023-04-06T12:50:00+00:00
[2023-04-08T10:12:18.431+0000] {subprocess.py:63} INFO - Tmp dir root location: 
 /tmp
[2023-04-08T10:12:18.464+0000] {subprocess.py:75} INFO - Running command: ['/bin/bash', '-c', 'echo "Doing Hi in Italian!!"']
[2023-04-08T10:12:18.997+0000] {subprocess.py:86} INFO - Output:
[2023-04-08T10:12:19.158+0000] {subprocess.py:93} INFO - Doing Hi in Italian!!
[2023-04-08T10:12:19.177+0000] {subprocess.py:97} INFO - Command exited with return code 0
[2023-04-08T10:12:20.891+0000] {taskinstance.py:1332} INFO - Marking task as SUCCESS. dag_id=io_resto_casa, task_id=say_Hi, execution_date=20230406T125000, start_date=20230408T101153, end_date=20230408T101220
[2023-04-08T10:12:24.410+0000] {local_task_job.py:212} INFO - Task exited with return code 0
[2023-04-08T10:12:33.543+0000] {taskinstance.py:2596} INFO - 0 downstream tasks scheduled from follow-on schedule check
