[2023-04-06T12:50:49.732+0000] {taskinstance.py:1090} INFO - Dependencies all met for dep_context=non-requeueable deps ti=<TaskInstance: io_resto_casa.say_Hi scheduled__2023-04-06T12:00:00+00:00 [queued]>
[2023-04-06T12:50:51.275+0000] {taskinstance.py:1090} INFO - Dependencies all met for dep_context=requeueable deps ti=<TaskInstance: io_resto_casa.say_Hi scheduled__2023-04-06T12:00:00+00:00 [queued]>
[2023-04-06T12:50:51.296+0000] {taskinstance.py:1288} INFO - 
--------------------------------------------------------------------------------
[2023-04-06T12:50:51.325+0000] {taskinstance.py:1289} INFO - Starting attempt 1 of 3
[2023-04-06T12:50:51.344+0000] {taskinstance.py:1290} INFO - 
--------------------------------------------------------------------------------
[2023-04-06T12:50:52.697+0000] {taskinstance.py:1309} INFO - Executing <Task(BashOperator): say_Hi> on 2023-04-06 12:00:00+00:00
[2023-04-06T12:50:53.096+0000] {standard_task_runner.py:55} INFO - Started process 13099 to run task
[2023-04-06T12:50:53.381+0000] {standard_task_runner.py:82} INFO - Running: ['***', 'tasks', 'run', 'io_resto_casa', 'say_Hi', 'scheduled__2023-04-06T12:00:00+00:00', '--job-id', '242', '--raw', '--subdir', 'DAGS_FOLDER/ciao.py', '--cfg-path', '/tmp/tmprixkos0y']
[2023-04-06T12:50:53.538+0000] {standard_task_runner.py:83} INFO - Job 242: Subtask say_Hi
[2023-04-06T14:29:38.196+0000] {task_command.py:389} INFO - Running <TaskInstance: io_resto_casa.say_Hi scheduled__2023-04-06T12:00:00+00:00 [running]> on host cfece00ff772
[2023-04-06T14:29:49.106+0000] {local_task_job.py:277} WARNING - State of this instance has been externally set to up_for_retry. Terminating instance.
[2023-04-06T14:29:50.805+0000] {process_utils.py:133} INFO - Sending Signals.SIGTERM to group 13099. PIDs of all processes in the group: [13099]
[2023-04-06T14:29:51.140+0000] {process_utils.py:84} INFO - Sending the signal Signals.SIGTERM to group 13099
[2023-04-06T14:29:51.482+0000] {taskinstance.py:1488} ERROR - Received SIGTERM. Terminating subprocesses.
[2023-04-06T14:29:52.696+0000] {subprocess.py:104} INFO - Sending SIGTERM signal to process group
[2023-04-06T14:29:57.619+0000] {taskinstance.py:1776} ERROR - Task failed with exception
Traceback (most recent call last):
  File "/home/airflow/.local/lib/python3.7/site-packages/airflow/models/taskinstance.py", line 1383, in _run_raw_task
    self._execute_task_with_callbacks(context, test_mode)
  File "/home/airflow/.local/lib/python3.7/site-packages/airflow/models/taskinstance.py", line 1496, in _execute_task_with_callbacks
    self.clear_xcom_data()
  File "/home/airflow/.local/lib/python3.7/site-packages/airflow/utils/session.py", line 75, in wrapper
    return func(*args, session=session, **kwargs)
  File "/home/airflow/.local/lib/python3.7/site-packages/airflow/models/taskinstance.py", line 865, in clear_xcom_data
    session=session,
  File "/home/airflow/.local/lib/python3.7/site-packages/airflow/utils/session.py", line 72, in wrapper
    return func(*args, **kwargs)
  File "/home/airflow/.local/lib/python3.7/site-packages/airflow/models/xcom.py", line 608, in clear
    query = session.query(cls).filter_by(dag_id=dag_id, task_id=task_id, run_id=run_id)
  File "/home/airflow/.local/lib/python3.7/site-packages/sqlalchemy/orm/query.py", line 1808, in filter_by
    for key, value in kwargs.items()
  File "/home/airflow/.local/lib/python3.7/site-packages/sqlalchemy/orm/query.py", line 1808, in <listcomp>
    for key, value in kwargs.items()
  File "/home/airflow/.local/lib/python3.7/site-packages/sqlalchemy/sql/operators.py", line 387, in __eq__
    return self.operate(eq, other)
  File "/home/airflow/.local/lib/python3.7/site-packages/sqlalchemy/orm/attributes.py", line 317, in operate
    return op(self.comparator, *other, **kwargs)
  File "/home/airflow/.local/lib/python3.7/site-packages/sqlalchemy/sql/operators.py", line 387, in __eq__
    return self.operate(eq, other)
  File "/home/airflow/.local/lib/python3.7/site-packages/sqlalchemy/orm/properties.py", line 426, in operate
    return op(self.__clause_element__(), *other, **kwargs)
  File "/home/airflow/.local/lib/python3.7/site-packages/sqlalchemy/util/langhelpers.py", line 1231, in oneshot
    result = fn(*args, **kw)
  File "/home/airflow/.local/lib/python3.7/site-packages/sqlalchemy/orm/properties.py", line 390, in _memoized_method___clause_element__
    return self._orm_annotate_column(self.prop.columns[0])
  File "/home/airflow/.local/lib/python3.7/site-packages/airflow/models/taskinstance.py", line 1490, in signal_handler
    raise AirflowException("Task received SIGTERM signal")
airflow.exceptions.AirflowException: Task received SIGTERM signal
[2023-04-06T14:30:05.183+0000] {taskinstance.py:1332} INFO - Marking task as UP_FOR_RETRY. dag_id=io_resto_casa, task_id=say_Hi, execution_date=20230406T120000, start_date=20230406T125049, end_date=20230406T143003
[2023-04-06T14:30:11.842+0000] {standard_task_runner.py:105} ERROR - Failed to execute job 242 for task say_Hi (Task received SIGTERM signal; 13099)
[2023-04-06T14:30:19.213+0000] {process_utils.py:79} INFO - Process psutil.Process(pid=13099, status='terminated', exitcode=1, started='12:50:52') (13099) terminated with exit code 1
