[2023-04-06T03:23:03.775+0000] {taskinstance.py:1090} INFO - Dependencies all met for dep_context=non-requeueable deps ti=<TaskInstance: io_resto_casa.greet scheduled__2023-04-06T03:10:00+00:00 [queued]>
[2023-04-06T03:23:03.793+0000] {taskinstance.py:1090} INFO - Dependencies all met for dep_context=requeueable deps ti=<TaskInstance: io_resto_casa.greet scheduled__2023-04-06T03:10:00+00:00 [queued]>
[2023-04-06T03:23:03.795+0000] {taskinstance.py:1288} INFO - 
--------------------------------------------------------------------------------
[2023-04-06T03:23:03.796+0000] {taskinstance.py:1289} INFO - Starting attempt 1 of 1
[2023-04-06T03:23:03.798+0000] {taskinstance.py:1290} INFO - 
--------------------------------------------------------------------------------
[2023-04-06T03:23:03.825+0000] {taskinstance.py:1309} INFO - Executing <Task(PythonOperator): greet> on 2023-04-06 03:10:00+00:00
[2023-04-06T03:23:03.835+0000] {standard_task_runner.py:55} INFO - Started process 572 to run task
[2023-04-06T03:23:03.841+0000] {standard_task_runner.py:82} INFO - Running: ['***', 'tasks', 'run', 'io_resto_casa', 'greet', 'scheduled__2023-04-06T03:10:00+00:00', '--job-id', '28', '--raw', '--subdir', 'DAGS_FOLDER/ciao.py', '--cfg-path', '/tmp/tmpwzpm6bhu']
[2023-04-06T03:23:03.847+0000] {standard_task_runner.py:83} INFO - Job 28: Subtask greet
[2023-04-06T03:23:03.958+0000] {task_command.py:389} INFO - Running <TaskInstance: io_resto_casa.greet scheduled__2023-04-06T03:10:00+00:00 [running]> on host cfece00ff772
[2023-04-06T03:23:04.049+0000] {taskinstance.py:1518} INFO - Exporting the following env vars:
AIRFLOW_CTX_DAG_OWNER=***
AIRFLOW_CTX_DAG_ID=io_resto_casa
AIRFLOW_CTX_TASK_ID=greet
AIRFLOW_CTX_EXECUTION_DATE=2023-04-06T03:10:00+00:00
AIRFLOW_CTX_TRY_NUMBER=1
AIRFLOW_CTX_DAG_RUN_ID=scheduled__2023-04-06T03:10:00+00:00
[2023-04-06T03:23:04.052+0000] {logging_mixin.py:137} INFO - Writing in file
[2023-04-06T03:23:04.054+0000] {taskinstance.py:1776} ERROR - Task failed with exception
Traceback (most recent call last):
  File "/home/airflow/.local/lib/python3.7/site-packages/airflow/operators/python.py", line 175, in execute
    return_value = self.execute_callable()
  File "/home/airflow/.local/lib/python3.7/site-packages/airflow/operators/python.py", line 192, in execute_callable
    return self.python_callable(*self.op_args, **self.op_kwargs)
  File "/opt/airflow/dags/ciao.py", line 14, in greet
    print(f.read())
ValueError: I/O operation on closed file.
[2023-04-06T03:23:04.073+0000] {taskinstance.py:1332} INFO - Marking task as FAILED. dag_id=io_resto_casa, task_id=greet, execution_date=20230406T031000, start_date=20230406T032303, end_date=20230406T032304
[2023-04-06T03:23:04.088+0000] {standard_task_runner.py:105} ERROR - Failed to execute job 28 for task greet (I/O operation on closed file.; 572)
[2023-04-06T03:23:04.136+0000] {local_task_job.py:212} INFO - Task exited with return code 1
[2023-04-06T03:23:04.187+0000] {taskinstance.py:2596} INFO - 0 downstream tasks scheduled from follow-on schedule check
